<?xml version="1.0" encoding="utf-8" standalone="yes"?>
<rss version="2.0" xmlns:atom="http://www.w3.org/2005/Atom" xmlns:content="http://purl.org/rss/1.0/modules/content/">
  <channel>
    <title>fastapi on dullmode</title>
    <link>https://dullmode.github.io/tags/fastapi/</link>
    <description>Recent content in fastapi on dullmode</description>
    <image>
      <url>https://imgur.com/a/SR2UQt7</url>
      <link>https://imgur.com/a/SR2UQt7</link>
    </image>
    <generator>Hugo -- gohugo.io</generator>
    <language>ja-jp</language>
    <lastBuildDate>Tue, 22 Mar 2022 14:55:31 +0900</lastBuildDate><atom:link href="https://dullmode.github.io/tags/fastapi/index.xml" rel="self" type="application/rss+xml" />
    <item>
      <title>fastapi&#43;uvicornでInvalid HTTP request received</title>
      <link>https://dullmode.github.io/posts/2022-03-22/</link>
      <pubDate>Tue, 22 Mar 2022 14:55:31 +0900</pubDate>
      
      <guid>https://dullmode.github.io/posts/2022-03-22/</guid>
      <description>invalid HTTP request received 本番環境でfastapiを動かしている時に以下のエラーが出力されました。
INFO: Started server process [9806] INFO: Waiting for application startup. INFO: Application startup complete. INFO: Uvicorn running on http://0.0.0.0:8000 (Press CTRL+C to quit) WARNING: Invalid HTTP request received. Traceback (most recent call last): File &amp;#34;/home/ec2-user/.local/lib/python3.7/site-packages/uvicorn/protocols/http/h11_impl.py&amp;#34;, line 170, in handle_events event = self.conn.next_event() File &amp;#34;/home/ec2-user/.local/lib/python3.7/site-packages/h11/_connection.py&amp;#34;, line 443, in next_event exc._reraise_as_remote_protocol_error() File &amp;#34;/home/ec2-user/.local/lib/python3.7/site-packages/h11/_util.py&amp;#34;, line 76, in _reraise_as_remote_protocol_error raise self File &amp;#34;/home/ec2-user/.local/lib/python3.7/site-packages/h11/_connection.py&amp;#34;, line 425, in next_event event = self.</description>
    </item>
    
  </channel>
</rss>
